Workbook

Sheet Frazaro
B1: # The arrays' fixture (KERNEL.8, slice f): a Data sheet of numbers in A1:A6 (unsorted, two alike), texts in B1:B5 | C1: OK
B2: # in two cases above an empty B6, numbers in C1:C6, a mixed column in D (a number, a text, a truth value, an empty | C2: OK
B3: # cell, zero and a negative), a matrix of three rows and two columns in E1:F3 and a column of two in G1:G2, an error | C3: OK
B4: # and a number in H1:H2, and 0.3 beside 0.1+0.2 in I1:I2; and a Functions sheet of one formula a rule from row 10: | C4: OK
B5: # array constants and the lift of an operator and of a value parameter over them, in legacy formulas; | C5: OK
B6: # SUMPRODUCT, ROWS and COLUMNS; SEQUENCE, FILTER, SORT, SORTBY, UNIQUE, TRANSPOSE and MMULT; the shapers | C6: OK
B7: # CHOOSECOLS, CHOOSEROWS, TAKE, DROP, HSTACK, VSTACK, TOCOL, TOROW, WRAPROWS, WRAPCOLS and EXPAND; a range read | C7: OK
B8: # whole in a dynamic formula (one calling an array function, as the build writes it); the lookups over arrays; `:` | C8: OK
B9: # between expressions; empty cells in arrays, and the edges Excel's documentation is silent on. Two formulas in D1 | C9: OK
B10: # and G1 spill, room left beside them. Built by frazaro into arrays.xlsx (each value it computes held). The owner | C10: OK
B11: # types three legacy array formulas into K1:K3 with Ctrl+Shift+Enter in Excel and saves it as arrays_saved.xlsx. | C11: OK
B13: Work on sheet Data. | C13: OK
... B256: Put formula "=LEN(CONCAT(REPT(""x"",20000),REPT(""y"",20000)))" into cell A214. | C256: OK

Sheet data
A1: 3 | B1: pear | C1: 10 | D1: 2 | E1: 1 | F1: 2 | G1: 7 | H1: =1/0 -> #DIV/0! | I1: 0.3
A2: 1 | B2: Apple | C2: 20 | D2: x | E2: 3 | F2: 4 | G2: 8 | H2: 7 | I2: =0.1+0.2 -> 0.3
A3: 4 | B3: fig | C3: 30 | D3: =TRUE -> TRUE | E3: 5 | F3: 6
A4: 1 | B4: apple | C4: 40
A5: 5 | B5: Date | C5: 50 | D5: 0
A6: 9 | C6: 60 | D6: -1

Sheet functions
D1: {=_xlfn.SEQUENCE(2,2)} -> 1 | E1: 2 | G1: {=_xlfn._xlws.FILTER(data!A1:A6,data!A1:A6>4)} -> 5 | K1: {=SUM(LEN(data!B1:B6))} -> 21
D2: 3 | E2: 4 | G2: 9 | K2: {=data!A1:A1*2} -> 6
K3: {=MAX(data!A1:A6*data!C1:C6)} -> 540
A10: =SUM({1,2;3,4}) -> 10
A11: =SUM({1,"2",TRUE}) -> 1
A12: =COUNTA({1,"a",TRUE,#N/A}) -> 4
A13: =COUNT({1,"2",TRUE}) -> 1
A14: =AVERAGE({1,2,3,4}) -> 2.5
A15: =MAX({-1,-5;3,0}) -> 3
A16: =AND({TRUE,1}) -> TRUE
A17: =OR({FALSE,0}) -> FALSE
A18: ={1,2,3} -> 1
A19: ={-1,2}*2 -> -2
A20: =SUM({1,2,3}*{4,5,6}) -> 32
A21: =SUM({1,2,3}+{10;20}) -> 102
A22: =SUM({1,2,3}+{10,20}) -> #N/A
A23: =SUM(LEN({"a","bc","def"})) -> 6
A24: =SUM(IF({TRUE,FALSE,TRUE},{1,2,3},{10,20,30})) -> 24
A25: =SUM(IF({TRUE,FALSE,TRUE},{1,2},0)) -> #N/A
A26: =SUM(IF({FALSE,FALSE,FALSE},{1,2},5)) -> 15
A27: {=SUM(CHOOSE({1,2},10,20))} -> 30
A28: =SUM(IFERROR({1,#N/A,3},0)) -> 1
A29: =SUM(IFERROR({1,2,3},{10,20})) -> 1
A30: =SUM(ISNUMBER({1,"a",TRUE})*1) -> 1
A31: =SUM(COUNTIF(data!A1:A6,{1,3})) -> 3
A32: =SUM(SUMIF(data!A1:A6,{1,5},data!C1:C6)) -> 110
A33: =SUM(VLOOKUP(3,data!A1:C6,{1,3},FALSE)) -> 3
A34: =MATCH(4,{3,1,4},0) -> 3
A35: =SUM(-{1,2}) -> -3
A36: =SUM({50,150}%) -> 2
A37: =SUM(({1,2,3}>1)*1) -> 2
A38: =SUMPRODUCT({1,2},{3,4}) -> 11
A39: =SUMPRODUCT(data!A1:A6,data!C1:C6) -> 1000
A40: =SUMPRODUCT(data!A1:A6*data!C1:C6) -> 1000
A41: =SUMPRODUCT((data!A1:A6>2)*data!C1:C6) -> 150
A42: =SUMPRODUCT(--(data!A1:A6>2)) -> 4
A43: =SUMPRODUCT((data!A1:A6>2)*1,data!C1:C6) -> 150
A44: =SUMPRODUCT(data!A1:A6,data!C1:C5) -> #VALUE!
A45: =SUMPRODUCT({1,"a",TRUE},{1,1,1}) -> 1
A46: =SUMPRODUCT(data!D1:D6) -> 1
...
