Workbook

Sheet Frazaro
B1: # The aggregates by criteria's fixture (KERNEL.8, slice e): a Data sheet of twelve records under names in row 1 (an | C1: OK
B2: # account, one blank and one in lower case; a month, one a text spelling 3; a region, its cases mixed; an amount; a | C2: OK
B3: # quantity; a note of wildcards, an empty text, texts beginning alike and texts spelling numbers; a mixed column of a | C3: OK
B4: # truth value, a text spelling 5, two errors and a blank; a day), criteria ranges for the database functions in K | C4: OK
B5: # to AL, and a SUBTOTAL among the cells it sums in X; a Far sheet of three keys and a cell below them in another | C5: OK
B6: # column; and a Functions sheet of one formula a function and a rule: the aggregates and their newer names, SUBTOTAL | C6: OK
B7: # by every number, SUMIFS, COUNTIFS, AVERAGEIF, AVERAGEIFS, MAXIFS and MINIFS, and the twelve database functions, | C7: OK
B8: # the edges Excel's documentation is silent on among them, and the reach of the rules Excel's first save settled. | C8: OK
B9: # Built by frazaro into criteria.xlsx (each value it computes held). The owner hides the Data sheet's row 6 in | C9: OK
B10: # Excel and saves it as criteria_saved.xlsx: SUBTOTAL's 101 to 111 pass that row by, and its 1 to 11 over it are | C10: OK
B11: # labelled. | C11: OK
B13: Work on sheet Data. | C13: OK
... B402: Put formula "=DSUM(Data!A1:H13,""Amount"",Data!K13:K15)" into cell A219. | C402: OK

Sheet data
A1: Account | B1: Month | C1: Region | D1: Amount | E1: Qty | F1: Note | G1: Mixed | H1: Day | K1: Region | L1: Note | M1: Note | N1: Month | O1: Account | P1: Month | Q1: Account | R1: Account | S1: region | T1: Nope | U1: Big | W1: Account | X1: 1 | Y1: Note | Z1: Note | AA1: Note | AB1: Amount | AC1: Amount | AD1: Amount | AE1: Account | AF1: Account | AG1: Account | AH1: Mixed | AI1: Account | AJ1: Month | AK1: Mixed | AL1: Amount
A2: Cash | B2: 1 | C2: East | D2: 100 | E2: 5 | F2: plain | G2: 1 | H2: 46023 | K2: East | L2: Dav | M2: =Dav | N2: 3 | O2: Cash | P2: 3 | Q2: Card | R2: Cash | S2: west | T2: x | U2: =Data!D2>100 -> FALSE | W2: Nope | X2: 2 | Y2: Dav* | Z2: *vi* | AA2: D?v | AB2: 10 | AC2: 10 | AD2: >100 | AE2: <>Cash | AF2: = | AG2: <> | AH2: =TRUE -> TRUE | AI2: Cash | AJ2: 3 | AK2: >1 | AL2: 300
A3: Bank | B3: 1 | C3: West | D3: 250.5 | E3: 3 | F3: a*b | G3: =TRUE -> TRUE | H3: 46024 | Q3: Bank | X3: =SUBTOTAL(9,X1:X2) -> 3 | AI3: Card
A4: Cash | B4: 2 | C4: east | D4: 75 | E4: 2 | F4: a?b | G4: 5 | H4: 46054 | X4: =SUBTOTAL(9,X1:X2)*2 -> 6
A5: Card | B5: 2 | C5: North | D5: 40 | E5: 1 | F5: ~tilde | G5: =1/0 -> #DIV/0! | H5: 46055 | X5: =SUM(X1:X2) -> 3
A6: Bank | B6: 3 | C6: West | D6: 300 | E6: 4 | H6: 46082
A7: Cash | B7: 3 | C7: East | D7: 125 | E7: 6 | F7: ="" | G7: 2 | H7: 46083
A8: Card | B8: 1 | C8: South | D8: -20 | E8: 7 | F8: Dav | G8: ="a"+1 -> #VALUE! | H8: 46025
A9: Cash | B9: 12 | C9: East | D9: 10 | E9: 0 | F9: Davolio | G9: 3 | H9: 46357
B10: 2 | C10: West | D10: 60 | E10: 2 | F10: David | G10: 4 | H10: 46056
A11: bank | B11: 2 | C11: WEST | D11: 0.1 | E11: 1 | F11: davis | G11: 5 | H11: 46057
A12: Cash | B12: 3 | C12: East | D12: 0.2 | E12: 9 | F12: 100 | G12: 6 | H12: 46084
A13: Card | B13: 3 | C13: North | D13: 55 | E13: 3 | F13: 1e2 | G13: 7 | H13: 46085

Sheet far
A1: Key | E1: Key
A2: x | E2: =
A3: y
C9: 1

Sheet functions
A1: =COUNT(Data!D2:D13) -> 12
A2: =COUNT(Data!G2:G13) -> 7
A3: =COUNT(1,TRUE,"2","x",1/0) -> 3
A4: =COUNT(1,,2) -> 3
A5: =COUNT(1/0) -> 0
A6: =COUNT(Data!J1) -> 0
A7: =COUNTA(Data!F2:F13) -> 11
A8: =COUNTA(1,"",TRUE,1/0) -> 4
A9: =COUNTA(Data!J1) -> 0
A10: =COUNTA(Data!F7) -> 1
A11: =COUNTA(1,,2) -> 3
A12: =PRODUCT(Data!E2:E5) -> 30
A13: =PRODUCT(Data!G2:G13) -> #DIV/0!
A14: =PRODUCT(2,"3",TRUE) -> 6
A15: =PRODUCT("x") -> #VALUE!
A16: =PRODUCT(Data!J1:J2) -> 0
A17: =PRODUCT(Data!D2:D13) -> -3.719925e+16
A18: =AVERAGE(Data!E2:E13) -> 3.5833333
A19: =AVERAGE(1,"2",TRUE) -> 1.3333333
A20: =AVERAGE(Data!J1:J2) -> #DIV/0!
A21: =AVERAGE(1,,2) -> 1
A22: =AVERAGE("x") -> #VALUE!
A23: =AVERAGE(TRUE) -> 1
A24: =AVERAGE(Data!D2:D13) -> 82.983333
A25: =VAR(1,2,3,4) -> 1.6666667
A26: =_xlfn.VAR.S(1,2,3,4) -> 1.6666667
A27: =VARP(1,2,3,4) -> 1.25
A28: =_xlfn.VAR.P(1,2,3,4) -> 1.25
A29: =STDEV(1,2,3,4) -> 1.2909944
A30: =_xlfn.STDEV.S(1,2,3,4) -> 1.2909944
A31: =STDEVP(1,2,3,4) -> 1.118034
A32: =_xlfn.STDEV.P(1,2,3,4) -> 1.118034
A33: =STDEV(5) -> #DIV/0!
A34: =STDEVP(5) -> 0
A35: =VARP(Data!J1) -> #DIV/0!
A36: =VAR(1000000001,1000000002,1000000003) -> 1
A37: =VAR(1E15+1,1E15+2,1E15+3) -> 1
A38: =VAR(0.1,0.2,0.3) -> 0.01
A39: =STDEV(0.1,0.2,0.3) -> 0.1
A40: =STDEV(Data!E2:E13) -> 2.7122059
...
