Workbook

Sheet Frazaro
B1: # The date functions' fixture (KERNEL.8, slice d): a Data sheet of the dates the functions read, serials of 2026's | C1: OK
B2: # first day, of 2024's leap day, of 1900's day that never was and of the calendar's day 0 and last day, a time, a | C2: OK
B3: # truth value, an error, texts a locale reads and one spelling a number, and holidays, one given twice, one on a | C3: OK
B4: # weekend, one empty and one far off, beside holidays of a text, a truth value and a date a locale reads; a Functions | C4: OK
B5: # sheet of one formula a function and a rule, each a legacy formula, the edges Excel's documentation is silent on | C5: OK
B6: # among them, arithmetic over the texts a locale reads, from row 298 the edges Excel's first save left the fold to | C6: OK
B7: # choose, which its second witnessed, from row 349 those its second left, for its third, and from row 360 the third's | C7: OK
B8: # reading of DATEDIF's "YD", for its fourth; and a Calendar sheet of every year from 1900 to 2101, a row each: its | C8: OK
B9: # first day's serial, February's length, the first day's weekday and ISO week, the year before's last day's year, | C9: OK
B10: # month and day, and the last day's ISO week, from which, with the months' fixed lengths, every day's YEAR, MONTH, DAY | C10: OK
B11: # and WEEKDAY follow. Built by frazaro into dates.xlsx (each value it computes held); the owner's save of it is | C11: OK
B12: # dates_saved.xlsx. | C12: OK
... B414: Put formula "=WEEKNUM(DATE(1899+ROW(),12,31),21)" into range E1:E202. | C414: OK

Sheet data
A1: 46023 | B1: 46027 | C1: 46027 | D1: 46027 | E1: 46027 | F1: 1,000
A2: 45351 | B2: 46028 | C2: 46028 | D2: =TRUE -> TRUE | E2: 1/6/2026 | F2: $5
A3: 60 | B3: 46027 | F3: 12abc
A4: 0 | B4: 46032 | F4: 5
A5: 46023.75
A6: =TRUE -> TRUE | B6: 46100
A7: 1/1/2026
A8: abc
A9: =1/0 -> #DIV/0!
A10: 46023
A11: 2958465
A12: 45659

Sheet functions
A1: =DATE(2026,1,1) -> 46023
A2: =DATE(1900,1,1) -> 1
A3: =DATE(1900,1,0) -> 0
A4: =DATE(1900,2,28) -> 59
A5: =DATE(1900,2,29) -> 60
A6: =DATE(1900,2,30) -> 61
A7: =DATE(1900,3,0) -> 60
A8: =DATE(1900,3,1) -> 61
A9: =DATE(1900,0,31) -> #NUM!
A10: =DATE(1900,1,-1) -> #NUM!
A11: =DATE(108,1,2) -> 39449
A12: =DATE(1,1,1) -> 367
A13: =DATE(1899,12,31) -> 693962
A14: =DATE(2008,14,2) -> 39846
A15: =DATE(2008,-3,2) -> 39327
A16: =DATE(2008,1,35) -> 39482
A17: =DATE(2008,1,-15) -> 39432
A18: =DATE(-1,1,1) -> #NUM!
A19: =DATE(10000,1,1) -> #NUM!
A20: =DATE(10000,-11,1)
A21: =DATE(9999,12,31) -> 2958465
A22: =DATE(9999,12,32) -> #NUM!
A23: =DATE(9999,13,-31) -> #NUM!
A24: =DATE(2026.9,1.9,1.9) -> 46023
A25: =DATE(2026,1,-0.5) -> 46021
A26: =DATE(2026,-0.5,1) -> 45962
A27: =DATE(-0.5,1,1) -> #NUM!
A28: =DATE(1899.9,1,1) -> 693598
A29: =DATE("2026",1,1) -> 46023
A30: =DATE(TRUE,1,1) -> 367
A31: =DATE(Data!A9,1,1) -> #DIV/0!
A32: =DATE(2026,1,Data!F1)
A33: =YEAR(Data!A1) -> 2026
A34: =MONTH(Data!A1) -> 1
A35: =DAY(Data!A1) -> 1
A36: =YEAR(Data!A2) -> 2024
A37: =MONTH(Data!A2) -> 2
A38: =DAY(Data!A2) -> 29
A39: =YEAR(Data!A3) -> 1900
A40: =MONTH(Data!A3) -> 2
...

Sheet calendar
A1: =DATE(1899+ROW(),1,1) -> 1 | B1: =DAY(EOMONTH(A1,1)) -> 28 | C1: =WEEKDAY(A1)*100+WEEKNUM(A1,21) -> 152 | D1: =YEAR(A1-1)*10000+MONTH(A1-1)*100+DAY(A1-1) -> 19000100 | E1: =WEEKNUM(DATE(1899+ROW(),12,31),21) -> 1
A2: =DATE(1899+ROW(),1,1) -> 367 | B2: =DAY(EOMONTH(A2,1)) -> 28 | C2: =WEEKDAY(A2)*100+WEEKNUM(A2,21) -> 301 | D2: =YEAR(A2-1)*10000+MONTH(A2-1)*100+DAY(A2-1) -> 19001231 | E2: =WEEKNUM(DATE(1899+ROW(),12,31),21) -> 1
A3: =DATE(1899+ROW(),1,1) -> 732 | B3: =DAY(EOMONTH(A3,1)) -> 28 | C3: =WEEKDAY(A3)*100+WEEKNUM(A3,21) -> 401 | D3: =YEAR(A3-1)*10000+MONTH(A3-1)*100+DAY(A3-1) -> 19011231 | E3: =WEEKNUM(DATE(1899+ROW(),12,31),21) -> 1
A4: =DATE(1899+ROW(),1,1) -> 1097 | B4: =DAY(EOMONTH(A4,1)) -> 28 | C4: =WEEKDAY(A4)*100+WEEKNUM(A4,21) -> 501 | D4: =YEAR(A4-1)*10000+MONTH(A4-1)*100+DAY(A4-1) -> 19021231 | E4: =WEEKNUM(DATE(1899+ROW(),12,31),21) -> 53
A5: =DATE(1899+ROW(),1,1) -> 1462 | B5: =DAY(EOMONTH(A5,1)) -> 29 | C5: =WEEKDAY(A5)*100+WEEKNUM(A5,21) -> 653 | D5: =YEAR(A5-1)*10000+MONTH(A5-1)*100+DAY(A5-1) -> 19031231 | E5: =WEEKNUM(DATE(1899+ROW(),12,31),21) -> 52
A6: =DATE(1899+ROW(),1,1) -> 1828 | B6: =DAY(EOMONTH(A6,1)) -> 28 | C6: =WEEKDAY(A6)*100+WEEKNUM(A6,21) -> 152 | D6: =YEAR(A6-1)*10000+MONTH(A6-1)*100+DAY(A6-1) -> 19041231 | E6: =WEEKNUM(DATE(1899+ROW(),12,31),21) -> 52
A7: =DATE(1899+ROW(),1,1) -> 2193 | B7: =DAY(EOMONTH(A7,1)) -> 28 | C7: =WEEKDAY(A7)*100+WEEKNUM(A7,21) -> 201 | D7: =YEAR(A7-1)*10000+MONTH(A7-1)*100+DAY(A7-1) -> 19051231 | E7: =WEEKNUM(DATE(1899+ROW(),12,31),21) -> 1
A8: =DATE(1899+ROW(),1,1) -> 2558 | B8: =DAY(EOMONTH(A8,1)) -> 28 | C8: =WEEKDAY(A8)*100+WEEKNUM(A8,21) -> 301 | D8: =YEAR(A8-1)*10000+MONTH(A8-1)*100+DAY(A8-1) -> 19061231 | E8: =WEEKNUM(DATE(1899+ROW(),12,31),21) -> 1
A9: =DATE(1899+ROW(),1,1) -> 2923 | B9: =DAY(EOMONTH(A9,1)) -> 29 | C9: =WEEKDAY(A9)*100+WEEKNUM(A9,21) -> 401 | D9: =YEAR(A9-1)*10000+MONTH(A9-1)*100+DAY(A9-1) -> 19071231 | E9: =WEEKNUM(DATE(1899+ROW(),12,31),21) -> 53
A10: =DATE(1899+ROW(),1,1) -> 3289 | B10: =DAY(EOMONTH(A10,1)) -> 28 | C10: =WEEKDAY(A10)*100+WEEKNUM(A10,21) -> 653 | D10: =YEAR(A10-1)*10000+MONTH(A10-1)*100+DAY(A10-1) -> 19081231 | E10: =WEEKNUM(DATE(1899+ROW(),12,31),21) -> 52
A11: =DATE(1899+ROW(),1,1) -> 3654 | B11: =DAY(EOMONTH(A11,1)) -> 28 | C11: =WEEKDAY(A11)*100+WEEKNUM(A11,21) -> 752 | D11: =YEAR(A11-1)*10000+MONTH(A11-1)*100+DAY(A11-1) -> 19091231 | E11: =WEEKNUM(DATE(1899+ROW(),12,31),21) -> 52
A12: =DATE(1899+ROW(),1,1) -> 4019 | B12: =DAY(EOMONTH(A12,1)) -> 28 | C12: =WEEKDAY(A12)*100+WEEKNUM(A12,21) -> 152 | D12: =YEAR(A12-1)*10000+MONTH(A12-1)*100+DAY(A12-1) -> 19101231 | E12: =WEEKNUM(DATE(1899+ROW(),12,31),21) -> 52
... A202: =DATE(1899+ROW(),1,1) -> 73416 | B202: =DAY(EOMONTH(A202,1)) -> 28 | C202: =WEEKDAY(A202)*100+WEEKNUM(A202,21) -> 752 | D202: =YEAR(A202-1)*10000+MONTH(A202-1)*100+DAY(A202-1) -> 21001231 | E202: =WEEKNUM(DATE(1899+ROW(),12,31),21) -> 52
