Workbook

Sheet Frazaro
B1: # The formulas read by a formula's fixture (KERNEL.53): a Data sheet whose column A holds a number, a text, an | C1: OK
B2: # empty cell and formulas of every kind FORMULATEXT spells (a plain one, a range read whole, a truth value, a text | C2: OK
B3: # holding a quote mark, spaces, small letters, a newer function the file prefixes, a function the language does | C3: OK
B4: # not hold), the legacy formulas Excel 365 may show with an @ beside those it does not, and a dynamic formula; a | C4: OK
B5: # fill over B1:B4; numbers in C1:C3; and in D1 a sum, which Excel shows with no @, for the owner to enter again | C5: OK
B6: # as a legacy array formula (its first formula, SUM(C1:C3*2), Excel's bar showed with an @, entered again with it). An | C6: OK
B7: # Other sheet holds one formula, so that Data:Other is a span of sheets. A Functions sheet holds one formula a | C7: OK
B8: # rule: ISFORMULA and FORMULATEXT of each kind of cell, a reference of many cells where one value is wanted (its | C8: OK
B9: # first cell or its own row's, A3 and A5 telling them apart), the same read as arrays (SUMPRODUCT, ROWS and a | C9: OK
B10: # dynamic INDEX) and handed whole to SUM and COUNTA in a legacy formula, a span of sheets, #REF!, a reference | C10: OK
B11: # through INDEX and IF, and each reading its own cell. Built | C11: OK
B12: # by frazaro into formulas.xlsx (each value it computes held). The owner enters Data!D1 again with Ctrl+Shift+Enter | C12: OK
... B114: Put formula "=FORMULATEXT(Data!A27)" into cell A63. | C114: OK

Sheet data
A1: 10 | B1: =A1+100 -> 110 | C1: 1 | D1: {=SUM(C1:C3)} -> 6
A2: x | B2: =A2+100 -> #VALUE! | C2: 2
A3: =A1*2 -> 20 | B3: =A3+100 -> 120 | C3: 3
B4: =A4+100 -> 100
A5: =SUM(A1:A3) -> 30
A6: =TRUE -> TRUE
A7: ="a""b" -> a"b
A8: =A1 + 1 -> 11
A9: =SUM(A1:A2) -> 10
A10: =_xlfn.CONCAT("a","b") -> ab
A11: =C1:C3 -> #VALUE!
A12: =C1:C3*2 -> #VALUE!
A13: {=INDEX(C1:C3,2)} -> 2
A14: =ROW(C1:C3) -> 1
A15: =IF(A1>5,C1,C2) -> 1
A16: =C1:C3 -> #VALUE!
A17: =VLOOKUP(1,C1:C3,1,FALSE) -> 1
A18: =COUNTIF(C1:C3,">1") -> 2
A19: =SUM(FACT(3)) -> 6
A20: =LEN(C1:C3) -> #VALUE!
A21: =SUM(C1:C3*2) -> #VALUE!
A22: =SUMPRODUCT(C1:C3*2) -> 12
A23: =SUM(IF(A1>5,C1:C3,0)) -> 6
A24: =-C1 -> -1
A25: =IFERROR(C1:C3,0) -> 0
A26: =SUM(ROW(C1:C3)) -> 1
A27: =SUMPRODUCT(ROW(C1:C3)) -> 6

Sheet other
A1: =data!A1*3 -> 30

Sheet functions
A1: =_xlfn.ISFORMULA(data!A1) -> FALSE
A2: =_xlfn.ISFORMULA(data!A2) -> FALSE
A3: =_xlfn.ISFORMULA(data!A1:A20) -> FALSE
A4: =_xlfn.ISFORMULA(data!A3) -> TRUE
A5: =_xlfn.FORMULATEXT(data!A1:A20) -> #N/A
A6: =_xlfn.ISFORMULA(data!A4) -> FALSE
A7: =_xlfn.ISFORMULA(data!A6) -> TRUE
A8: =_xlfn.ISFORMULA(data!B1) -> TRUE
A9: =_xlfn.ISFORMULA(data!B3) -> TRUE
A10: =_xlfn.ISFORMULA(data!A13) -> TRUE
A11: =_xlfn.ISFORMULA(data!D1) -> TRUE
A12: =_xlfn.ISFORMULA(other!A1) -> TRUE
A13: {=_xlfn.ISFORMULA(INDEX(data!A1:A8,3))} -> TRUE
A14: =_xlfn.ISFORMULA(IF(TRUE,data!A3,data!A1)) -> TRUE
A15: =_xlfn.ISFORMULA(#REF!) -> #REF!
A16: =_xlfn.ISFORMULA(data:other!A1) -> #VALUE!
A17: =_xlfn.ISFORMULA(A17) -> TRUE
A18: =SUMPRODUCT(--_xlfn.ISFORMULA(data!A1:A8)) -> 5
A19: =SUMPRODUCT(--_xlfn.ISFORMULA(data!A1:B4)) -> 5
A20: =SUMPRODUCT(--_xlfn.ISFORMULA(data!B:B)) -> 4
A21: =NOT(_xlfn.ISFORMULA(data!A1)) -> TRUE
A22: =_xlfn.FORMULATEXT(data!A1) -> #N/A
A23: =_xlfn.FORMULATEXT(data!A3) -> =A1*2
A24: =_xlfn.FORMULATEXT(data!A4) -> #N/A
A25: =_xlfn.FORMULATEXT(data!A5) -> =SUM(A1:A3)
A26: =_xlfn.FORMULATEXT(data!A6) -> =TRUE
A27: =_xlfn.FORMULATEXT(data!A7) -> ="a""b"
A28: =_xlfn.FORMULATEXT(data!A8) -> =A1 + 1
A29: =_xlfn.FORMULATEXT(data!A9) -> =SUM(A1:A2)
A30: =_xlfn.FORMULATEXT(data!A10) -> =CONCAT("a","b")
A31: =_xlfn.FORMULATEXT(data!A11) -> =@C1:C3
A32: =_xlfn.FORMULATEXT(data!A12) -> =@C1:C3*2
A33: =_xlfn.FORMULATEXT(data!A13) -> =INDEX(C1:C3,2)
A34: =_xlfn.FORMULATEXT(data!A14) -> =@ROW(C1:C3)
... A45: =_xlfn.FORMULATEXT(data!A25) -> =IFERROR(@C1:C3,0)
A46: =_xlfn.FORMULATEXT(data!B1) -> =A1+100
A47: =_xlfn.FORMULATEXT(data!B3) -> =A3+100
A48: =_xlfn.FORMULATEXT(data!D1) -> {=SUM(C1:C3)}
A49: =_xlfn.FORMULATEXT(other!A1) -> =data!A1*3
A50: =_xlfn.FORMULATEXT(data:other!A1) -> #VALUE!
...
