Workbook

Sheet Frazaro
B1: # The lookups' fixture (KERNEL.8, slice a): one formula per function, mode and rule the slice computes, over a | C1: OK
B2: # Table sheet of vectors: ascending, descending, texts in two cases (letters alone, so that every rule orders them | C2: OK
B3: # alike), every kind with an empty cell, an error and duplicates, and unsorted vectors on which the bisection's | C3: OK
B4: # candidate rules answer differently. The Criteria sheet holds SUMIF and COUNTIF over the equality an index keys and | C4: OK
B5: # the sizes and patterns the scan answers, an error in a sum range at a row met and at a row not met, and the two | C5: OK
B6: # questions the equality turns on: a letter's case beyond ASCII, and two numbers equal to fifteen digits alone. | C6: OK
B7: # Built by frazaro into lookups.xlsx (each value it computes held); the owner's save of it is lookups_saved.xlsx. | C7: OK
B9: Work on sheet Table. | C9: OK
B10: Put 10 into cell A1. | C10: OK
B11: Put 20 into cell A2. | C11: OK
B12: Put 30 into cell A3. | C12: OK
B13: Put 40 into cell A4. | C13: OK
... B279: Put formula "=COUNTIF(A1:A12,""<15"")" into cell H38. | C279: OK

Sheet table
A1: 10 | B1: r1 | C1: 80 | D1: apple | E1: 5 | F1: 50 | G1: 10
A2: 20 | B2: r2 | C2: 70 | D2: Banana | E2: 5 | F2: 10 | G2: x
A3: 30 | B3: r3 | C3: 60 | D3: cherry | E3: =TRUE -> TRUE | F3: 70 | G3: 20
A4: 40 | B4: r4 | C4: 50 | D4: Date | F4: 20 | G4: y
A5: 50 | B5: r5 | C5: 40 | D5: elder | E5: =1/0 -> #DIV/0! | F5: 80 | G5: 30
A6: 60 | B6: r6 | C6: 30 | D6: Fig | E6: 5 | F6: 30 | G6: =TRUE -> TRUE
A7: 70 | B7: r7 | C7: 20 | D7: grape | E7: x | F7: 60 | G7: 40
A8: 80 | B8: r8 | C8: 10 | D8: Hazel | E8: X | F8: 40
E9: 0 | G9: 50
E10: =FALSE -> FALSE
A12: 1 | B12: 2 | C12: 3 | D12: 4 | E12: 5 | F12: 6 | G12: 7 | H12: 8
A13: one | B13: two | C13: three | D13: four | E13: five | F13: six | G13: seven | H13: eight

Sheet lookups
A1: =MATCH(30,Table!A1:A8,0) -> 3
A2: =MATCH(35,Table!A1:A8,1) -> 3
A3: =MATCH(35,Table!A1:A8) -> 3
A4: =MATCH(5,Table!A1:A8) -> #N/A
A5: =MATCH(99,Table!A1:A8) -> 8
A6: =MATCH(35,Table!C1:C8,-1) -> 5
A7: =MATCH(5,Table!C1:C8,-1) -> 8
A8: =MATCH(99,Table!C1:C8,-1) -> #N/A
A9: =MATCH("BANANA",Table!D1:D8,0) -> 2
A10: =MATCH("b*",Table!D1:D8,0) -> 2
A11: =MATCH("?ig",Table!D1:D8,0) -> 6
A12: =MATCH("*e*",Table!D1:D8,0) -> 1
A13: =MATCH("cherrz",Table!D1:D8,1) -> 3
A14: =MATCH("5",Table!E1:E10,0) -> 2
A15: =MATCH(5,Table!E1:E10,0) -> 1
A16: =MATCH(TRUE,Table!E1:E10,0) -> 3
A17: =MATCH("X",Table!E1:E10,0) -> 7
A18: =MATCH(0,Table!E1:E10,0) -> 9
A19: =MATCH(FALSE,Table!E1:E10,0) -> 10
A20: =MATCH(30,Table!A1:B8,0) -> #N/A
A21: =MATCH(35,Table!A1:A8,) -> #N/A
A22: =MATCH(3,Table!A12:H12,0) -> 3
A23: =MATCH(45,Table!F1:F8,1) -> 6
A24: =MATCH(25,Table!F1:F8,1) -> 4
A25: =MATCH(65,Table!F1:F8) -> 8
A26: =MATCH(15,Table!F1:F8,-1) -> 1
A27: =MATCH(35,Table!G1:G9,1) -> 5
A28: =MATCH("xa",Table!G1:G9,1) -> 2
A29: =MATCH(TRUE,Table!G1:G9,1) -> 6
A30: =MATCH(Table!E5,Table!A1:A8,0) -> #DIV/0!
A31: =_xlfn.XMATCH("banana",Table!D1:D8) -> 2
A32: =_xlfn.XMATCH(35,Table!A1:A8) -> #N/A
A33: =_xlfn.XMATCH(35,Table!A1:A8,1) -> 4
A34: =_xlfn.XMATCH(35,Table!A1:A8,-1) -> 3
A35: =_xlfn.XMATCH(35,Table!A1:A8,1,2) -> 4
A36: =_xlfn.XMATCH(35,Table!A1:A8,-1,2) -> 3
A37: =_xlfn.XMATCH(35,Table!C1:C8,1,-2) -> 5
A38: =_xlfn.XMATCH(35,Table!C1:C8,-1,-2) -> 6
A39: =_xlfn.XMATCH("c*",Table!D1:D8,2) -> 3
A40: =_xlfn.XMATCH("c*",Table!D1:D8) -> #N/A
...

Sheet criteria
A1: 10 | B1: 1 | C1: 1 | D1: a | E1: =0.1+0.2 -> 0.3 | F1: É | H1: =COUNTIF(A1:A12,20) -> 3
A2: 20 | B2: 2 | C2: =1/0 -> #DIV/0! | D2: b | F2: é | H2: =COUNTIF(A1:A12,"20") -> 3
A3: 30 | B3: 3 | C3: 3 | D3: a | F3: e | H3: =COUNTIF(A1:A12,"=20") -> 3
A4: 20 | B4: 4 | C4: 4 | D4: b | H4: =COUNTIF(A1:A12,"<>20") -> 10
A5: 20 | B5: 5 | H5: =COUNTIF(A1:A12,">15") -> 3
A6: x | B6: 6 | H6: =COUNTIF(A1:A12,"x") -> 2
A7: X | B7: 7 | H7: =COUNTIF(A1:A12,"x*") -> 2
A8: =TRUE -> TRUE | B8: 8 | H8: =COUNTIF(A1:A12,"?") -> 2
B9: 9 | H9: =COUNTIF(A1:A12,"*") -> 3
A10: 0 | B10: 10 | H10: =COUNTIF(A1:A12,"") -> 1
A11: 0 | B11: 11 | H11: =COUNTIF(A1:A12,"<>") -> 11
A12: 5 | B12: 12 | H12: =COUNTIF(A1:A12,TRUE) -> 1
H13: =COUNTIF(A1:A12,"TRUE") -> 1
H14: =COUNTIF(A1:A12,0) -> 2
H15: =COUNTIF(A1:A12,A4) -> 3
H16: =COUNTIF(A1:A12,A9) -> 2
H17: =SUMIF(A1:A12,20,B1:B12) -> 11
H18: =SUMIF(A1:A12,">15",B1:B12) -> 9
H19: =SUMIF(A1:A12,"x*",B1:B12) -> 13
H20: =SUMIF(A1:A12,"<>20",B1:B12) -> 72
H21: =SUMIF(A1:A12,"",B1:B12) -> 9
H22: =SUMIF(A1:A12,20) -> 40
H23: =SUMIF(D1:D4,"a",C1:C4) -> 4
H24: =SUMIF(D1:D4,"b",C1:C4) -> #DIV/0!
H25: =COUNTIF(C1:C4,1) -> 1
H26: =COUNTIF(C1:C4,"#DIV/0!") -> 1
H27: =SUMIF(A1:A12,20,B1)
H28: =SUMIF(A1:A3,">15",B1:B12) -> 5
H29: =F1=F2 -> TRUE
H30: =0.1+0.2=0.3 -> TRUE
H31: =MATCH(0.3,E1,0) -> #N/A
H32: =COUNTIF(E1,0.3) -> 1
H33: =VLOOKUP(0.3,E1,1,FALSE) -> #N/A
H34: =COUNTIF(F1:F3,F2) -> 2
H35: =MATCH(F2,F1:F3,0) -> 1
H36: =SUMIF(F1:F3,F1,B1:B3) -> 3
H37: =COUNTIF(A1:A12,"<>x") -> 10
H38: =COUNTIF(A1:A12,"<15") -> 4
