Workbook

Sheet Frazaro
B1: # The text functions' fixture (KERNEL.8, slice c): a Data sheet of the texts the functions read, words and spaces, an | C1: OK
B2: # apostrophe and digits among letters, letters beyond ASCII, an emoji (a surrogate pair, two UTF-16 units) first and | C2: OK
B3: # between letters, a number, a truth value and an error, a row of texts with an empty cell among them, delimiters, and | C3: OK
B4: # texts a locale might read; a Functions sheet of one formula a function and a rule, each a legacy formula, TEXT's | C4: OK
B5: # dates and times among them, and the comparisons the order of texts answers; and an Order sheet of characters and | C5: OK
B6: # texts, each beside its rank among them, SUMPRODUCT(--(range<text)), which this version does not compute: the | C6: OK
B7: # order's golden, Excel's own ranks, read off its save. Built by frazaro into texts.xlsx (each value it computes | C7: OK
B8: # held); the owner's save of it is texts_saved.xlsx. | C8: OK
B10: Work on sheet Data. | C10: OK
B11: Put "Hello World" into cell A1. | C11: OK
B12: Put " lots of space " into cell A2. | C12: OK
B13: Put "o'neil 2nd-place" into cell A3. | C13: OK
... B550: Put formula "=SUMPRODUCT(--($A$1:$A$163<A163))" into cell B163. | C550: OK

Sheet data
A1: Hello World | B1: x | C1: 1,000 | D1: -
A2: lots of space | C2: 12abc | D2: +
A3: o'neil 2nd-place | B3: z | C3: 50%
A4: Éclair ß | C4: 7
A5: 😀ab | C5: abc
A6: a😀b
A7: 123.5
A8: =TRUE -> TRUE
A9: =1/0 -> #DIV/0!

Sheet functions
A1: =LEN(data!A1) -> 11
A2: =LEN(data!A5) -> 3
A3: =LEN(data!A7) -> 5
A4: =LEN(data!A8) -> 4
A5: =LEN("") -> 0
A6: =LEN(data!A9) -> #DIV/0!
A7: =LEFT(data!A1) -> H
A8: =LEFT(data!A1,5) -> Hello
A9: =LEFT(data!A1,99) -> Hello World
A10: =LEFT(data!A1,0)
A11: =LEFT(data!A1,2.9) -> He
A12: =LEFT(data!A1,-1) -> #VALUE!
A13: =LEFT(data!A1,-0.5) -> #VALUE!
A14: =LEFT(1234,2) -> 12
A15: =LEFT(data!A5,2) -> 😀a
A16: =LEFT(data!A5,1) -> 😀
A17: =RIGHT(data!A1,5) -> World
A18: =RIGHT(data!A6,3) -> a😀b
A19: =RIGHT(data!A6,2) -> 😀b
A20: =MID(data!A1,7,5) -> World
A21: =MID(data!A1,7,99) -> World
A22: =MID(data!A1,20,5)
A23: =MID(data!A1,0,5) -> #VALUE!
A24: =MID(data!A1,1,-1) -> #VALUE!
A25: =MID(data!A6,2,2) -> 😀b
A26: =MID(data!A6,3,1) -> b
A27: =MID(data!A1,1.9,2) -> He
A28: =FIND("o",data!A1) -> 5
A29: =FIND("o",data!A1,6) -> 8
A30: =FIND("O",data!A1) -> #VALUE!
A31: =FIND("x",data!A1) -> #VALUE!
A32: =FIND("o",data!A1,0) -> #VALUE!
A33: =FIND("o",data!A1,12) -> #VALUE!
A34: =FIND("",data!A1) -> 1
A35: =FIND("",data!A1,3) -> 3
A36: =FIND("",data!A1,12) -> 12
A37: =FIND("","") -> 1
A38: =FIND("b",data!A6) -> 3
A39: =SEARCH("O",data!A1) -> 5
A40: =SEARCH("w?r",data!A1) -> 7
...

Sheet order
B1: =SUMPRODUCT(--($A$1:$A$163<A1)) -> 3
A2: ! | B2: =SUMPRODUCT(--($A$1:$A$163<A2)) -> 6
A3: " | B3: =SUMPRODUCT(--($A$1:$A$163<A3)) -> 7
A4: # | B4: =SUMPRODUCT(--($A$1:$A$163<A4)) -> 8
A5: $ | B5: =SUMPRODUCT(--($A$1:$A$163<A5)) -> 9
A6: % | B6: =SUMPRODUCT(--($A$1:$A$163<A6)) -> 10
A7: & | B7: =SUMPRODUCT(--($A$1:$A$163<A7)) -> 11
A8: ' | B8: =SUMPRODUCT(--($A$1:$A$163<A8)) -> 0
A9: ( | B9: =SUMPRODUCT(--($A$1:$A$163<A9)) -> 12
A10: ) | B10: =SUMPRODUCT(--($A$1:$A$163<A10)) -> 13
A11: * | B11: =SUMPRODUCT(--($A$1:$A$163<A11)) -> 14
A12: + | B12: =SUMPRODUCT(--($A$1:$A$163<A12)) -> 36
A13: , | B13: =SUMPRODUCT(--($A$1:$A$163<A13)) -> 15
... A129: ’ | B129: =SUMPRODUCT(--($A$1:$A$163<A129)) -> 34
B130: =SUMPRODUCT(--($A$1:$A$163<A130)) -> 5
A131: Ω | B131: =SUMPRODUCT(--($A$1:$A$163<A131)) -> 159
A132: α | B132: =SUMPRODUCT(--($A$1:$A$163<A132)) -> 158
A133: Ж | B133: =SUMPRODUCT(--($A$1:$A$163<A133)) -> 160
A134: 日 | B134: =SUMPRODUCT(--($A$1:$A$163<A134)) -> 162
A135: 😀 | B135: =SUMPRODUCT(--($A$1:$A$163<A135)) -> 161
A136: co-op | B136: =SUMPRODUCT(--($A$1:$A$163<A136)) -> 87
A137: coop | B137: =SUMPRODUCT(--($A$1:$A$163<A137)) -> 86
A138: co op | B138: =SUMPRODUCT(--($A$1:$A$163<A138)) -> 84
A139: coo | B139: =SUMPRODUCT(--($A$1:$A$163<A139)) -> 85
A140: cop | B140: =SUMPRODUCT(--($A$1:$A$163<A140)) -> 88
A141: a- | B141: =SUMPRODUCT(--($A$1:$A$163<A141)) -> 58
A142: -a | B142: =SUMPRODUCT(--($A$1:$A$163<A142)) -> 59
... A159: a1 | B159: =SUMPRODUCT(--($A$1:$A$163<A159)) -> 66
B160: =SUMPRODUCT(--($A$1:$A$163<A160)) -> 4
A161: aa | B161: =SUMPRODUCT(--($A$1:$A$163<A161)) -> 70
A162: aA | B162: =SUMPRODUCT(--($A$1:$A$163<A162)) -> 70
A163: Aa | B163: =SUMPRODUCT(--($A$1:$A$163<A163)) -> 70
